<?xml version="1.0" ?>
<sdf version="1.8">
    <model name="cart_pole">
        <link name="rail">
            <pose>0 0 0 0 0 0</pose>
            <inertial>
                <mass>1.0</mass>
                <inertia>
                    <ixx>0.01</ixx>
                    <ixy>0</ixy>
                    <ixz>0</ixz>
                    <iyy>0.01</iyy>
                    <iyz>0</iyz>
                    <izz>0.01</izz>
                </inertia>
            </inertial>
            <visual name="rail_visual">
                <geometry>
                    <box>
                        <size>3.0 0.1 0.1</size>
                    </box>
                </geometry>
                <material>
                    <ambient>0.5 0.5 0.5 1</ambient>
                    <diffuse>0.5 0.5 0.5 1</diffuse>
                    <specular>0.1 0.1 0.1 1</specular>
                </material>
            </visual>
            <collision name="rail_collision">
                <geometry>
                    <box>
                        <size>3.0 0.1 0.1</size>
                    </box>
                </geometry>
            </collision>
        </link>

        <link name="cart">
            <pose relative_to="rail">0 0 0.1 0 0 0</pose>
            <inertial>
                <mass>1.0</mass>
                <inertia>
                    <ixx>0.01</ixx>
                    <ixy>0</ixy>
                    <ixz>0</ixz>
                    <iyy>0.01</iyy>
                    <iyz>0</iyz>
                    <izz>0.01</izz>
                </inertia>
            </inertial>
            <visual name="cart_visual">
                <geometry>
                    <box>
                        <size>0.3 0.2 0.1</size>
                    </box>
                </geometry>
                <material>
                    <ambient>0 0 1 1</ambient>
                    <diffuse>0 0 1 1</diffuse>
                    <specular>0.1 0.1 0.1 1</specular>
                </material>
            </visual>
            <collision name="cart_collision">
                <geometry>
                    <box>
                        <size>0.3 0.2 0.1</size>
                    </box>
                </geometry>
            </collision>
        </link>

        <link name="pole">
            <pose relative_to="cart">0 0 0.05 0 0 0</pose>
            <inertial>
                <pose>0 0 0.5 0 0 0</pose>
                <mass>0.1</mass>
                <inertia>
                    <ixx>0.0083</ixx>
                    <ixy>0</ixy>
                    <ixz>0</ixz>
                    <iyy>0.0083</iyy>
                    <iyz>0</iyz>
                    <izz>0.001</izz>
                </inertia>
            </inertial>
            <visual name="pole_visual">
                <pose>0 0 0.5 0 0 0</pose>
                <geometry>
                    <cylinder>
                        <radius>0.025</radius>
                        <length>1.0</length>
                    </cylinder>
                </geometry>
                <material>
                    <ambient>1 0 0 1</ambient>
                    <diffuse>1 0 0 1</diffuse>
                    <specular>0.1 0.1 0.1 1</specular>
                </material>
            </visual>
            <collision name="pole_collision">
                <pose>0 0 0.5 0 0 0</pose>
                <geometry>
                    <cylinder>
                        <radius>0.025</radius>
                        <length>1.0</length>
                    </cylinder>
                </geometry>
            </collision>
        </link>

        <joint name="world_fixed" type="fixed">
            <parent>world</parent>
            <child>rail</child>
        </joint>

        <joint name="cart_slider" type="prismatic">
            <parent>rail</parent>
            <child>cart</child>
            <axis>
                <xyz>1 0 0</xyz>
                <limit>
                    <lower>-1.5</lower>
                    <upper>1.5</upper>
                    <effort>1000.0</effort>
                    <velocity>1000.0</velocity>
                </limit>
                <dynamics>
                    <damping>0.1</damping>
                    <friction>0.1</friction>
                </dynamics>
            </axis>
        </joint>

        <joint name="pole_hinge" type="revolute">
            <parent>cart</parent>
            <child>pole</child>
            <axis>
                <xyz>0 1 0</xyz>
                <limit>
                    <lower>-3.14159</lower>
                    <upper>3.14159</upper>
                    <effort>1000.0</effort>
                    <velocity>1000.0</velocity>
                </limit>
                <dynamics>
                    <damping>0.1</damping>
                    <friction>0.1</friction>
                </dynamics>
            </axis>
        </joint>

        <!-- Joint control plugin -->
        <plugin
            filename="gz-sim-joint-controller-system"
            name="gz::sim::systems::JointController">
            <joint_name>cart_slider</joint_name>
            <use_force_commands>true</use_force_commands>
        </plugin>

        <!-- Set initial pose -->
        <plugin
            filename="gz-sim-pose-publisher-system"
            name="gz::sim::systems::PosePublisher">
            <publish_link_pose>true</publish_link_pose>
            <use_pose_vector_msg>true</use_pose_vector_msg>
            <update_rate>100</update_rate>
        </plugin>

        <plugin
            filename="gz-sim-joint-state-publisher-system"
            name="gz::sim::systems::JointStatePublisher">
            <joint_name>cart_slider</joint_name>
            <joint_name>pole_hinge</joint_name>
        </plugin>
    </model>
</sdf> 